Workbook

Sheet How to Read
B1: EV Readiness & Impact Index
B8: {={"HOW TO READ THIS SPREADSHEET"; ""; "OVERVIEW"; "This spreadsheet contains the underlying data for the Africa EV Readiness and Impact Indices, comprehensive frameworks for assessing African countries' preparedness for electric vehicle adoption and potential benefits. Here's how to navigate the informa"&"tion:"; ""; "1. MAIN SHEET"; "• Contains raw data for all indicators across both indices"; "• Organized by major categories (Enabling Policies, Grid Infrastructure, etc.)"; "• Includes links to source data and methodology notes"; "• Shows latest available data for each indicator"; ""; "2. SCORING TABS"; ""; "Readiness Total Scores Tab:"; "• Shows normalized scores (1/3, 2/3, 3/3) for readiness indicators"; "• Calculates averages with and without enabling policies"; "• Provides category-level scores"; ""; "Impact Total Scores Tab:"; "• Shows normalized scores (1/3, 2/3, 3/3) for impact indicators"; "• Calculates overall impact averages"; ""; "3. INDICATOR-SPECIFIC TABS"; "• Each indicator has its own detailed tab"; "• Contains raw data, calculations, and methodological notes"; "• Features an information box (approx. cell C65) with:"; " - Index category and sub-category"; " - Detailed description"; " - Scoring methodology"; " - Data sources"; " - Key statistics"; ""; "4. INDACTOR SCORING METHODOLOGY"; "Full methodologies can be found in methodology note [link at the bottom of page]"; ""; "Readiness Indicators:"; "• Low Readiness: 1/3 (0.33)"; "• Medium Readiness: 2/3 (0.67)"; "• High Readiness: 3/3 (1.00)"; "• Some indicators use binary scoring (1/3 or 3/3 only)"; "• A country's aggregate readiness score is calculated by averaging indicator scores (equal weigthing)"; ""; "Impact Indicators:"; "• Low Impact: 1/3 (0.33)"; "• Medium Impact: 2/3 (0.67)"; "• High Impact: 3/3 (1.00)"; "• A country's aggregate readiness score is calculated by averaging indicator scores (equal weigthing)"; ""; "5. CATEGORY BREAKDOWN"; ""; "Readiness Categories:"; "• Enabling Policies: National targets and incentives"; "• Grid Infrastructure: Generation capacity and reliability"; "• Market: Current motorization and charging infrastructure"; "• Power Sector Maturity: Regulatory environment and financial health"; "• EV Affordability: Relative costs and financial access"; ""; "Impact Categories:"; "• Climate: Clean energy share and transport emissions"; "• Public Health: Urban air quality"; "• Financial: Import dependence and revenue potential"; "• Market Potential: Projected motorization rates"; ""; "6. DATA UPDATES"; "• Latest comprehensive update: 2024"; "• Individual indicator dates vary (see main tab)"}} -> HOW TO READ THIS SPREADSHEET
B10: OVERVIEW
B11: This spreadsheet contains the underlying data for the Africa EV Readiness and Impact Indices, comprehensive frameworks for assessing African countries' preparedness for electric vehicle adoption and potential benefits. Here's how to navigate the information:
B13: 1. MAIN SHEET
B14: • Contains raw data for all indicators across both indices
B15: • Organized by major categories (Enabling Policies, Grid Infrastructure, etc.)
B16: • Includes links to source data and methodology notes
B17: • Shows latest available data for each indicator
B19: 2. SCORING TABS
B21: Readiness Total Scores Tab:
B22: • Shows normalized scores (1/3, 2/3, 3/3) for readiness indicators
B23: • Calculates averages with and without enabling policies
B24: • Provides category-level scores
... B75: Full methodology

Sheet Overview
B1: MAIN SHEET
B2: Tab | C2: Summary | D2: Notes
B3: Main Sheet | C3: Synthesizes database | D3: Compares metrics for all 54 African countries
B5: CATEGORIES
B6: Tab | C6: Summary | D6: Notes
B7: Readiness | C7: 10 Indicators | D7: Summarizes readiness indicators
B8: Impact | C8: 7 Indicators | D8: Summarizes impact indicators
B10: Full information on data sources and other indicator details can be found in the methodology note [link to methodology note]
B12: READINESS INDICATORS
B13: Sub-Category | C13: Tab | D13: Summary
B14: Enabling Policies | C14: EV National Targets | D14: Official policies, ambitions, or targets to support EV deployment.
C15: EV Incentives | D15: Legally binding commitments such as standards, regulations, and exemptions.
B16: Grid Infrastructure | C16: Additional Capacity for 30% EVs | D16: Additional electricity generation necessary to meet the power demand of converting 30% of current road transportation to electric.
C17: Reliability | D17: Annual average duration of electricity outages in a country as reported in WB Enterprise Surveys OR SAIDI data reported in WB Doing Business.
B18: Market Potential | C18: Current rate of motorization | D18: The number of vehicles per 1,000 inhabitants as a proxy for potential market size (includes all vehicle classes).
C19: EV Charging infrastructure | D19: Number of public EV charging points as a proxy for EV deployment/penetration (Data was benchmarked against EV companies to account for non-traditional charging business models).
B20: Power Sector Maturity | C20: Electricity Regulatory Index | D20: AfDB’s composite index that assesses regulatory and legal dimensions of power sector development in African countries.
C21: Utility Financial Solvency | D21: Utility financial performance data from the World Bank, used as a proxy for utility quality.
B22: EV Affordability | C22: Relative Affordability of Electric Charging | D22: Cost ratio of electricity to gasoline needed for equivalent EV and ICE car models to travel 100 miles.
C23: Access to Finance Indicator | D23: % of population over the age of 15 years old that have borrowed money from a formal financial institution or using a mobile money account.
B25: IMPACT INDICATORS
B26: Sub-Category | C26: Tab | D26: Summary
B27: Climate | C27: % Electricity Generated from Clean Energy / Share of Clean Electricity Generation | D27: Percentage of electricity currently generated from clean energy sources.
C28: % CO2 from Transportation | D28: Percentage of CO2 from transportation calculated by Transport CO2/CO2 from fuel combustion*100.
B29: Public Health | C29: Urban Air Quality | D29: The Air Quality Index (AQI) is a common indicator (scale) for reporting daily air quality. The AQI measures carbon monoxide, nitrogen dioxide, sulfur dioxide, ozone, and 24-hour PM2.5 and PM10. Comprehensive urban AQI measurements for African countries is parse, with only real time data available for a select few countries. Due to the lack of real time data available, our indicator is a composite custom AQI constructed by getting a weighted average of the pollutants.
B30: Financial | C30: Fossil Fuel Import Dependence | D30: Current fossil fuel import burden as a proxy for energy security.
C31: Fossil Fuel Subsidy Burden | D31: Expenditure on explicit subsidies for gasoline and diesel consumers expressed as a % of GDP.
C32: Utility Revenue Potential | D32: Potential utility revenues from selling electricity if 30% of current road transport fleet is electrified.
B33: Cross-cutting | C33: Projected rate of motorization 2050 | D33: Projection of number of passenger cars per 1,000 inhabitants per country in 2050, with implications for scale. of impacts across all dimensions

Sheet Scoring - Readiness
B1: READINESS INDICATORS SCORING
B2: Link to full methodology [here]
B3: Sub-Category | C3: Indicator | D3: Low Readiness | E3: Medium Readiness | F3: High Readiness | G3: Scoring rationale
D4: 45294 | E4: 45325 | F4: 1
B5: Enabling Policies | C5: EV National Targets | D5: No | E5: - | F5: Yes | G5: High Readiness: At least one instance of the indicator is identified in the examined country Medium Readiness: N/A; this is a binary indicator Low Readiness: No instance of the indicator is identified in the examined country
C6: EV Incentives | D6: No | E6: - | F6: Yes | G6: High Readiness: At least one instance of the indicator is identified in the examined country Medium Readiness: N/A; this is a binary indicator Low Readiness: No instance of the indicator is identified in the examined country
B7: Grid Infrastrucutre | C7: Additional Generation for 30% EVs | D7: Large expansion [>1.25] | E7: Medium expansion [1.25-1.1] | F7: Modest expansion [<1.1] | G7: IEA projects Africa's overall electricity demand will grow 4% annually for the next two years (2024-26). In 10 years, a country's electricity demand will have grown ~50% at this rate. If meeting 30% EV penetration target requires more than half of this estimated 10 year growth, the readiness has been deemed as low.
C8: Grid Reliability | D8: Low WBES:[>250] SAIDI:[>20] | E8: Medium WBES:[50-250] SAIDI:[5-20] | F8: High WBES:[<50] SAIDI:[<5] | G8: Thresholds for WBES and SAIDI were benchmarked against EU + North America (High reliability) and Asia, Caribbean and South America (Medium reliability).
B9: Market | C9: Current Rate of Motorization | D9: Low [<100] | E9: Medium [100-200] | F9: High [>200] | G9: Most developed countries have a motorization rate north of 500, and many developing countries have rates below 150. Global average is 300 and developing country average is 180. Select examples: India 159; China 210; UK 579; EU average 560.
C10: EV Charging Infrastructure | D10: Low [<10] | E10: Medium [10-30] | F10: High [>30] | G10: Bounds are based on the spread of African EV charging point data (regional benchmarking).
B11: Power Sector Maturity | C11: Electricity Regulatory Index (as proxy for utility quality) | D11: Low [<0.5] | E11: Medium [0.5-0.8] | F11: High [>0.8] | G11: The ERI scores on AfDB’s Africa Energy Portal (AEP) are sorted into four categories. Our medium category is a combination of both ERI medium categories.
C12: Utility Cost Recovery | D12: Low [<85%] | E12: Medium [85-100%] | F12: High [>100%] | G12: Our scoring category cutoffs aligns with conventional cost recovery bounds. Mature utilities are profitable and cost recovery is the norm. The WB adopts this framework in their conclusion that the financial health of many Africa utilities is sub-par as they do not cover their costs.
B13: EV Affordability | C13: Relative Affordability | D13: EV pricier [>1] | E13: Comparable [0.75-1] | F13: EV cheaper [<0.75] | G13: This indicator compares the cost of operating an electric vehicle (EV) to that of a gasoline-powered internal combustion engine (ICE) vehicle, specifically looking at the cost to drive 100 miles. When EV charging is more expensive than gasoline, it reflects lower affordability for EVs in terms of operating costs. An "EV Pricier" rating means that the ICE vehicle is significantly cheaper to drive—costing 74.9% or less of what it would cost to drive an EV the same distance. "Parity" indicates that the operating costs of the two vehicle types are roughly equivalent, with the ICE vehicle costing between 75% and 100% of the EV's cost. When EVs are the more economical option, the indicator is labeled "EV Cheaper," meaning the ICE vehicle costs more than 100% of the EV's cost to drive 100 miles.
C14: Access to Finance Indicator - Borrowed any money from a formal financial institution or using a mobile money account (% age 15+) | D14: Low [<20%] | E14: Medium [20-40%] | F14: High [>40%] | G14: The world average in this indicator is 30% and has been chosen as a guide for the medium readiness category. The Middle East (11%), South Asia (12%), and SSA (14%) are on the lower ends and have guided the lower bounds of our indicator scoring in the low readiness category.

Sheet Scoring - Impact
B1: IMPACT INDICATORS SCORING
B2: Link to full methodology [here]
B3: Sub-Category | C3: Indicator | D3: Low Impact | E3: Medium Impact | F3: High Impact | G3: Scoring rationale
D4: 45294 | E4: 45325 | F4: 1
B5: Climate | C5: % Electricity Generated from Clean Energy | D5: Low [<33.33%] | E5: Medium [33.33-66.67%] | F5: High [>66.67%] | G5: The scoring has been divided into equal thirds, with more than two-thirds clean generation set as an ambitious bound for the highest category.
C6: % CO2 from Transportation | D6: Low [<33.33%] | E6: Medium [33-66.67%] | F6: High [>66.67%] | G6: he scoring has been divided into equal thirds.
B7: Public Health | C7: Urban Air Quality (AQI) | D7: Low [<100] | E7: Medium [100-200] | F7: High [>200] | G7: Custom AQI values were benchmarked against WHO interim air quality targets and categorized into low, moderate, high, very high, and serious. We further aggregated these into three high, medium and low categories.
B8: Financial | C8: Fossil Fuel Import Dependence | D8: Low [<33.33%] | E8: Medium [33.33-66.67%] | F8: High [>66.67%] | G8: The scoring has been divided into equal thirds.
C9: Subsidy Burden | D9: Low [0] | E9: Medium [>0-.5%] | F9: High [>0.5%] | G9: The average gasoline and diesel consumer subsidy burden in Africa is 0.57%, and has been used as a guide for the medium category. The low value is set at 0%, a decision guided by the fact that most countries are at 0% and the median is 0%.
C10: Utility Revenue Potential | D10: Low [<$30M] | E10: Medium [$30M-$110M] | F10: High [>$110M] | G10: Scoring categories have been selected based on the 33rd and 66th percentile to create low, medium, and high leverage categories (regional benchmarking). 33rd percentile: $30.3M, 66th percentile: 109.4M.
B11: Market Potential | C11: Projected Rate of Motorization (2050) | D11: Low [<100] | E11: Medium [100-200] | F11: High [>200] | G11: Most developed countries have a motorization rate north of 500, and many developing countries have rates below 150. Global average is 300 and developing country average is 180. Select examples: India 159; China 210; UK 579; EU average 560.

Sheet Main Sheet
A1: Country | B1: Readiness - Preparedness to adopt EVs at a large scale | L1: Impact - Broader benefits of EV adoption
B2: Enabling Policies | D2: Grid Infrastrucutre | F2: Market | H2: Power Sector Maturity | J2: EV Affordability | L2: Climate | N2: Public Health | O2: Financial | R2: Market Potential
B3: National Target (2023) | C3: EV Incentives (2023) | D3: Additional Generation for 30% EVs (multiplication factor) (2016-2022) | E3: Reliability (yearly average time without electricity, hours, various dates. SAIDI scores in yellow highlight. WBES scores w/o hightlight) (2010-2023) | F3: Current Rate of Motorization (2016) | G3: EV Charging Infrastructure (2024) | H3: ERI Score (2022) | I3: Utility Cost Recovery (Operating cost and debt service recovery, including subsidies) (2019) | J3: Relative Affordability - Gas vs Charging (EV cost per 100 miles / ICE cost per 100 miles) (2022-2024) | K3: Borrowed any money from a formal financial institution or using a mobile money account (% age 15+) (2014-2022) | L3: % Electricity generated from clean energy (2021) | M3: % CO2 Emissions from Transport (2020) | N3: Urban Air Quality (Custom AQI) (2019) | O3: Fossil Fuel Dependence (Ratio of transportation fuel consumption to net imports by country) (2021) | P3: Fossil Fuel Subsidy Burden (% of GDP, gasoline & diesel, explicit subsidies) (2023) | Q3: Utility Revenue Potential ($, 30% EVs) (2021) | R3: Projected rate of motorization (2050)
A4: Algeria | B4: =IF(countif('EV National Targets'!A:A,A4)>0, "1", "0") -> 1 | C4: =IF(countif('EV Incentives'!A:A,A4)>0, "1", "0") -> 0 | D4: {='Additional Generation For 30% E'!C2+1} -> 1.1664408 | E4: {='Grid Reliability'!K2} -> 4.2 | F4: {='Current Rate of Motorization'!B3} -> 30.183765 | G4: {='EV Charging Infrastructure'!B2} -> 6 | H4: {='Electricity Regulatory Index'!C2} -> 0.644 | I4: {=' Utility Cost Recovery'!B2} -> Not Found | J4: {='Relative Affordability'!F2} -> 0.26100215 | K4: {='Access to Finance'!C2} -> 0.04 | L4: {='Electricity Generated from Clea'!F2} -> 0.011696782 | M4: {='CO2 from Transportation'!E2} -> 0.30082794 | N4: {='Urban Air Quality'!I2} -> 193.23092 | O4: {='Fossil Fuel Import Dependence'!G2} -> -323.22222 | P4: {='Fossil Fuel Subsidy Burden'!E2} -> 0.074359566 | Q4: {='Utility Revenue Potential'!J2} -> 4.3874547e+08 | R4: {='Projected Rate of Motorization '!C2} -> 167.40233
A5: Angola | B5: =IF(countif('EV National Targets'!A:A,A5)>0, "1", "0") -> 0 | C5: =IF(countif('EV Incentives'!A:A,A5)>0, "1", "0") -> 1 | D5: {='Additional Generation For 30% E'!C3+1} -> 1.1015791 | E5: {='Grid Reliability'!K3} -> 12.8 | F5: {='Current Rate of Motorization'!B3} -> 30.183765 | G5: {='EV Charging Infrastructure'!B3} -> 2 | H5: {='Electricity Regulatory Index'!C3} -> 0.608 | I5: {=' Utility Cost Recovery'!B3} -> 0.73134225 | J5: {='Relative Affordability'!F3} -> 0.085032375 | K5: {='Access to Finance'!C3} -> Not Found | L5: {='Electricity Generated from Clea'!F3} -> 0.71323394 | M5: {='CO2 from Transportation'!E3} -> 0.37196201 | N5: {='Urban Air Quality'!I3} -> 320.40134 | O5: {='Fossil Fuel Import Dependence'!G3} -> 0.51760939 | P5: {='Fossil Fuel Subsidy Burden'!E3} -> 0.036522746 | Q5: {='Utility Revenue Potential'!J3} -> 20026599 | R5: {='Projected Rate of Motorization '!C3} -> 83.118222
A6: Benin | B6: =IF(countif('EV National Targets'!A:A,A6)>0, "1", "0") -> 0 | C6: =IF(countif('EV Incentives'!A:A,A6)>0, "1", "0") -> 1 | D6: {='Additional Generation For 30% E'!C4+1} -> 9.9972832 | E6: {='Grid Reliability'!F4} -> 1243.2 | F6: {='Current Rate of Motorization'!B4} -> 20.107308 | G6: {='EV Charging Infrastructure'!B4} -> Not Found | H6: {='Electricity Regulatory Index'!C4} -> 0.465 | I6: {=' Utility Cost Recovery'!B4} -> 0.92957926 | J6: {='Relative Affordability'!F4} -> 0.082832608 | K6: {='Access to Finance'!C4} -> 0.11 | L6: {='Electricity Generated from Clea'!F4} -> 0.033430489 | M6: {='CO2 from Transportation'!E4} -> 0.81071813 | N6: {='Urban Air Quality'!I4} -> 292.90165 | O6: {='Fossil Fuel Import Dependence'!G4} -> 0.99266324 | P6: {='Fossil Fuel Subsidy Burden'!E4} -> 0.005748186 | Q6: {='Utility Revenue Potential'!J4} -> 78092820 | R6: {='Projected Rate of Motorization '!C4} -> 122.42352
A7: Botswana | B7: =IF(countif('EV National Targets'!A:A,A7)>0, "1", "0") -> 0 | C7: =IF(countif('EV Incentives'!A:A,A7)>0, "1", "0") -> 0 | D7: {='Additional Generation For 30% E'!C5+1} -> 1.390465 | E7: {='Grid Reliability'!F5} -> 152.64 | F7: {='Current Rate of Motorization'!B5} -> 198.19921 | G7: {='EV Charging Infrastructure'!B5} -> 3 | H7: {='Electricity Regulatory Index'!C5} -> 0.527 | I7: {=' Utility Cost Recovery'!B5} -> 0.79266347 | J7: {='Relative Affordability'!F5} -> 0.26872867 | K7: {='Access to Finance'!C5} -> 0.11 | L7: {='Electricity Generated from Clea'!F5} -> 0.0027493322 | M7: {='CO2 from Transportation'!E5} -> 0.36920593 | N7: {='Urban Air Quality'!I5} -> 202.30469 | O7: {='Fossil Fuel Import Dependence'!G5} -> 0.82463856 | P7: {='Fossil Fuel Subsidy Burden'!E5} -> 0 | Q7: {='Utility Revenue Potential'!J5} -> 95438693 | R7: {='Projected Rate of Motorization '!C5} -> 399.46129
A8: Burkina Faso | B8: =IF(countif('EV National Targets'!A:A,A8)>0, "1", "0") -> 0 | C8: =IF(countif('EV Incentives'!A:A,A8)>0, "1", "0") -> 0 | D8: {='Additional Generation For 30% E'!C6+1} -> 1.5550016 | E8: {='Grid Reliability'!F6} -> 388.08 | F8: {='Current Rate of Motorization'!B6} -> 16.818502 | G8: {='EV Charging Infrastructure'!B6} -> 1 | H8: {='Electricity Regulatory Index'!C6} -> 0.495 | I8: {=' Utility Cost Recovery'!B6} -> 1.0414191 | J8: {='Relative Affordability'!F6} -> 0.82663283 | K8: {='Access to Finance'!C6} -> 0.09 | L8: {='Electricity Generated from Clea'!F6} -> 0.13299267 | M8: {='CO2 from Transportation'!E6} -> 0.54783967 | N8: {='Urban Air Quality'!I6} -> 251.65868 | O8: {='Fossil Fuel Import Dependence'!G6} -> 0.86084702 | P8: {='Fossil Fuel Subsidy Burden'!E6} -> 0.005313478 | Q8: {='Utility Revenue Potential'!J6} -> 4.3888597e+08 | R8: {='Projected Rate of Motorization '!C6} -> 67.572258
A9: Burundi | B9: =IF(countif('EV National Targets'!A:A,A9)>0, "1", "0") -> 0 | C9: =IF(countif('EV Incentives'!A:A,A9)>0, "1", "0") -> 0 | D9: {='Additional Generation For 30% E'!C7+1} -> 1.1524761 | E9: {='Grid Reliability'!F7} -> 956.16 | F9: {='Current Rate of Motorization'!B7} -> 4.0006138 | G9: {='EV Charging Infrastructure'!B7} -> Not Found | H9: {='Electricity Regulatory Index'!C7} -> 0.284 | I9: {=' Utility Cost Recovery'!B7} -> 1.1356048 | J9: {='Relative Affordability'!F7} -> 0.2892348 | K9: {='Access to Finance'!C7} -> Not Found | L9: {='Electricity Generated from Clea'!F7} -> 0.65305436 | M9: {='CO2 from Transportation'!E7} -> 0.79985925 | N9: {='Urban Air Quality'!I7} -> 281.19026 | O9: {='Fossil Fuel Import Dependence'!G7} -> 0.78947368 | P9: {='Fossil Fuel Subsidy Burden'!E7} -> 0 | Q9: {='Utility Revenue Potential'!J7} -> 8624416.7 | R9: {='Projected Rate of Motorization '!C7} -> 22.903843
A10: Cabo Verde | B10: =IF(countif('EV National Targets'!A:A,A10)>0, "1", "0") -> 1 | C10: =IF(countif('EV Incentives'!A:A,A10)>0, "1", "0") -> 1 | D10: {='Additional Generation For 30% E'!C8+1} -> 4.4049117 | E10: {='Grid Reliability'!K8} -> 18.3 | F10: {='Current Rate of Motorization'!B8} -> 4.2896671 | G10: {='EV Charging Infrastructure'!B8} -> Not Found | H10: {='Electricity Regulatory Index'!C8} -> 0.515 | I10: {=' Utility Cost Recovery'!B8} -> 0.96020938 | J10: {='Relative Affordability'!F8} -> 0.32589853 | K10: {='Access to Finance'!C8} -> Not Found | L10: {='Electricity Generated from Clea'!F8} -> 0.15977689 | M10: {='CO2 from Transportation'!E8} -> 0.46245569 | N10: {='Urban Air Quality'!I8} -> 179.60465 | O10: {='Fossil Fuel Import Dependence'!G8} -> 0.4966443 | P10: {='Fossil Fuel Subsidy Burden'!E8} -> 0 | Q10: {='Utility Revenue Potential'!J8} -> 14080887 | R10: {='Projected Rate of Motorization '!C8} -> 298.6468
A11: Cameroon | B11: =IF(countif('EV National Targets'!A:A,A11)>0, "1", "0") -> 0 | C11: =IF(countif('EV Incentives'!A:A,A11)>0, "1", "0") -> 0 | D11: {='Additional Generation For 30% E'!C9+1} -> 1.0087948 | E11: {='Grid Reliability'!F9} -> 793.44 | F11: {='Current Rate of Motorization'!B9} -> 116.32467 | G11: {='EV Charging Infrastructure'!B9} -> 5 | H11: {='Electricity Regulatory Index'!C9} -> 0.606 | I11: {=' Utility Cost Recovery'!B9} -> 0.69329753 | J11: {='Relative Affordability'!F9} -> 0.35545967 | K11: {='Access to Finance'!C9} -> 0.11 | L11: {='Electricity Generated from Clea'!F9} -> 0.62395322 | M11: {='CO2 from Transportation'!E9} -> 0.50090699 | N11: {='Urban Air Quality'!I9} -> 303.49876 | O11: {='Fossil Fuel Import Dependence'!G9} -> 1.0854922 | P11: {='Fossil Fuel Subsidy Burden'!E9} -> 0.0022912621 | Q11: {='Utility Revenue Potential'!J9} -> 2.3646186e+08 | R11: {='Projected Rate of Motorization '!C9} -> 102.64147
A12: Central African Republic | B12: =IF(countif('EV National Targets'!A:A,A12)>0, "1", "0") -> 0 | C12: =IF(countif('EV Incentives'!A:A,A12)>0, "1", "0") -> 0 | D12: {='Additional Generation For 30% E'!C10+1} -> 1.4951778 | E12: {='Grid Reliability'!F10} -> 2411.16 | F12: {='Current Rate of Motorization'!B10} -> 7.6414452 | G12: {='EV Charging Infrastructure'!B10} -> Not Found | H12: {='Electricity Regulatory Index'!C10} -> 0.292 | I12: {=' Utility Cost Recovery'!B10} -> 0.44246128 | J12: {='Relative Affordability'!F10} -> 0.21624707 | K12: {='Access to Finance'!C10} -> Not Found | L12: {='Electricity Generated from Clea'!F10} -> 0.99295663 | M12: {='CO2 from Transportation'!E10} -> 0.91293322 | N12: {='Urban Air Quality'!I10} -> 323.58562 | O12: {='Fossil Fuel Import Dependence'!G10} -> 0.83962264 | P12: {='Fossil Fuel Subsidy Burden'!E10} -> 0 | Q12: {='Utility Revenue Potential'!J10} -> 11369836 | R12: {='Projected Rate of Motorization '!C10} -> 20.600555
A13: Chad | B13: =IF(countif('EV National Targets'!A:A,A13)>0, "1", "0") -> 0 | C13: =IF(countif('EV Incentives'!A:A,A13)>0, "1", "0") -> 0 | D13: {='Additional Generation For 30% E'!C11+1} -> 2.2682715 | E13: {='Grid Reliability'!F11} -> 2881.08 | F13: {='Current Rate of Motorization'!B11} -> 77.025421 | G13: {='EV Charging Infrastructure'!B11} -> Not Found | H13: {='Electricity Regulatory Index'!C11} -> 0.147 | I13: {=' Utility Cost Recovery'!B11} -> 0.85134073 | J13: {='Relative Affordability'!F11} -> 0.47546416 | K13: {='Access to Finance'!C11} -> 0.1 | L13: {='Electricity Generated from Clea'!F11} -> 0.060813393 | M13: {='CO2 from Transportation'!E11} -> 0.76207426 | N13: {='Urban Air Quality'!I11} -> 274.25303 | O13: {='Fossil Fuel Import Dependence'!G11} -> -260.5 | P13: {='Fossil Fuel Subsidy Burden'!E11} -> 0 | Q13: {='Utility Revenue Potential'!J11} -> 60625647 | R13: {='Projected Rate of Motorization '!C11} -> 30.691011
A14: Comoros | B14: =IF(countif('EV National Targets'!A:A,A14)>0, "1", "0") -> 0 | C14: =IF(countif('EV Incentives'!A:A,A14)>0, "1", "0") -> 0 | D14: {='Additional Generation For 30% E'!C12+1} -> 1.1805057 | E14: {='Grid Reliability'!F12} -> Not Found | F14: {='Current Rate of Motorization'!B12} -> 46.765617 | G14: {='EV Charging Infrastructure'!B12} -> Not Found | H14: {='Electricity Regulatory Index'!C12} -> Not Found | I14: {=' Utility Cost Recovery'!B12} -> 1.0105691 | J14: {='Relative Affordability'!F12} -> 0.56517352 | K14: {='Access to Finance'!C12} -> 0.09 | L14: {='Electricity Generated from Clea'!F12} -> 0 | M14: {='CO2 from Transportation'!E12} -> 0.56611822 | N14: {='Urban Air Quality'!I12} -> 159.01925 | O14: {='Fossil Fuel Import Dependence'!G12} -> 0.81818182 | P14: {='Fossil Fuel Subsidy Burden'!E12} -> 0 | Q14: {='Utility Revenue Potential'!J12} -> 7530696.7 | R14: {='Projected Rate of Motorization '!C12} -> 103.05532
A15: Congo | B15: =IF(countif('EV National Targets'!A:A,A15)>0, "1", "0") -> 0 | C15: =IF(countif('EV Incentives'!A:A,A15)>0, "1", "0") -> 0 | D15: {='Additional Generation For 30% E'!C13+1} -> 1.1056025 | E15: {='Grid Reliability'!F13} -> 8849.4 | F15: {='Current Rate of Motorization'!B13} -> 4.3456265 | G15: {='EV Charging Infrastructure'!B13} -> 1 | H15: {='Electricity Regulatory Index'!C13} -> 0.101 | I15: {=' Utility Cost Recovery'!B13} -> Not Found | J15: {='Relative Affordability'!F13} -> 0.26079744 | K15: {='Access to Finance'!C13} -> 0.1 | L15: {='Electricity Generated from Clea'!F13} -> 0.2241695 | M15: {='CO2 from Transportation'!E13} -> 0.32391783 | N15: {='Urban Air Quality'!I13} -> 405.15523 | O15: {='Fossil Fuel Import Dependence'!G13} -> 3.4224138 | P15: {='Fossil Fuel Subsidy Burden'!E13} -> 0 | Q15: {='Utility Revenue Potential'!J13} -> 38633990 | R15: {='Projected Rate of Motorization '!C13} -> 125.87645
A16: Côte d'Ivoire | B16: =IF(countif('EV National Targets'!A:A,A16)>0, "1", "0") -> 0 | C16: =IF(countif('EV Incentives'!A:A,A16)>0, "1", "0") -> 0 | D16: {='Additional Generation For 30% E'!C14+1} -> 2.4488589 | E16: {='Grid Reliability'!F14} -> 155.4 | F16: {='Current Rate of Motorization'!B14} -> 3.0659601 | G16: {='EV Charging Infrastructure'!B14} -> 1 | H16: {='Electricity Regulatory Index'!C14} -> 0.573 | I16: {=' Utility Cost Recovery'!B14} -> 0.91329021 | J16: {='Relative Affordability'!F14} -> 0.38987418 | K16: {='Access to Finance'!C14} -> 0.08 | L16: {='Electricity Generated from Clea'!F15} -> 0.020963305 | M16: {='CO2 from Transportation'!E14} -> 0.38517422 | N16: {='Urban Air Quality'!I14} -> 302.3763 | O16: {='Fossil Fuel Import Dependence'!G14} -> -2.897281 | P16: {='Fossil Fuel Subsidy Burden'!E14} -> 0.0014281896 | Q16: {='Utility Revenue Potential'!J14} -> 3.3570532e+08 | R16: {='Projected Rate of Motorization '!C14} -> 214.39407
A17: Djibouti | B17: =IF(countif('EV National Targets'!A:A,A17)>0, "1", "0") -> 0 | C17: =IF(countif('EV Incentives'!A:A,A17)>0, "1", "0") -> 0 | D17: {='Additional Generation For 30% E'!C15+1} -> 1.060249 | E17: {='Grid Reliability'!F15} -> 28.8 | F17: {='Current Rate of Motorization'!B15} -> 39.090711 | G17: {='EV Charging Infrastructure'!B15} -> Not Found | H17: {='Electricity Regulatory Index'!C15} -> Not Found | I17: {=' Utility Cost Recovery'!B15} -> Not Found | J17: {='Relative Affordability'!F15} -> 0.5471275 | K17: {='Access to Finance'!C15} -> Not Found | L17: {='Electricity Generated from Clea'!F16} -> 0.999489 | M17: {='CO2 from Transportation'!E15} -> 0.41410218 | N17: {='Urban Air Quality'!I15} -> 161.86394 | O17: {='Fossil Fuel Import Dependence'!G15} -> 0.88571429 | P17: {='Fossil Fuel Subsidy Burden'!E15} -> 0 | Q17: {='Utility Revenue Potential'!J15} -> 24340829 | R17: {='Projected Rate of Motorization '!C15} -> 303.84345
A18: DR Congo | B18: =IF(countif('EV National Targets'!A:A,A18)>0, "1", "0") -> 0 | C18: =IF(countif('EV Incentives'!A:A,A18)>0, "1", "0") -> 1 | D18: {='Additional Generation For 30% E'!C16+1} -> 1.1505815 | E18: {='Grid Reliability'!F16} -> 826.56 | F18: {='Current Rate of Motorization'!B16} -> 0.72683642 | G18: {='EV Charging Infrastructure'!B16} -> 1 | H18: {='Electricity Regulatory Index'!C16} -> 0.527 | I18: {=' Utility Cost Recovery'!B16} -> 0.76470188 | J18: {='Relative Affordability'!F16} -> 0.1665452 | K18: {='Access to Finance'!C16} -> 0.05 | L18: {='Electricity Generated from Clea'!F14} -> 0.30148712 | M18: {='CO2 from Transportation'!E16} -> 0.99630822 | N18: {='Urban Air Quality'!I16} -> 293.77668 | O18: {='Fossil Fuel Import Dependence'!G16} -> 1 | P18: {='Fossil Fuel Subsidy Burden'!E16} -> 0 | Q18: {='Utility Revenue Potential'!J16} -> 51879930 | R18: {='Projected Rate of Motorization '!C16} -> 37.654797
A19: Egypt | B19: =IF(countif('EV National Targets'!A:A,A19)>0, "1", "0") -> 0 | C19: =IF(countif('EV Incentives'!A:A,A19)>0, "1", "0") -> 1 | D19: {='Additional Generation For 30% E'!C17+1} -> 1.0743223 | E19: {='Grid Reliability'!F17} -> 8.64 | F19: {='Current Rate of Motorization'!B17} -> 61.866593 | G19: {='EV Charging Infrastructure'!B17} -> 48 | H19: {='Electricity Regulatory Index'!C17} -> 0.785 | I19: {=' Utility Cost Recovery'!B17} -> Not Found | J19: {='Relative Affordability'!F17} -> 0.25654481 | K19: {='Access to Finance'!C17} -> 0.08 | L19: {='Electricity Generated from Clea'!F17} -> 0.11551545 | M19: {='CO2 from Transportation'!E17} -> 0.27374711 | N19: {='Urban Air Quality'!I17} -> 257.36063 | O19: {='Fossil Fuel Import Dependence'!G17} -> 4.0939879 | P19: {='Fossil Fuel Subsidy Burden'!E17} -> 0.031043672 | Q19: {='Utility Revenue Potential'!J17} -> 5.5618694e+08 | R19: {='Projected Rate of Motorization '!C17} -> 324.06148
A20: Equatorial Guinea | B20: =IF(countif('EV National Targets'!A:A,A20)>0, "1", "0") -> 0 | C20: =IF(countif('EV Incentives'!A:A,A20)>0, "1", "0") -> 0 | D20: {='Additional Generation For 30% E'!C18+1} -> 1.0185327 | E20: {='Grid Reliability'!F18} -> Not Found | F20: {='Current Rate of Motorization'!B18} -> 102.2212 | G20: {='EV Charging Infrastructure'!B18} -> Not Found | H20: {='Electricity Regulatory Index'!C18} -> Not Found | I20: {=' Utility Cost Recovery'!B18} -> Not Found | J20: {='Relative Affordability'!F18} -> 0.60900502 | K20: {='Access to Finance'!C18} -> Not Found | L20: {='Electricity Generated from Clea'!F18} -> 0.31026894 | M20: {='CO2 from Transportation'!E18} -> 0.11366801 | N20: {='Urban Air Quality'!I18} -> 295.8785 | O20: {='Fossil Fuel Import Dependence'!G18} -> 0.87837838 | P20: {='Fossil Fuel Subsidy Burden'!E18} -> 0.008312805 | Q20: {='Utility Revenue Potential'!J18} -> 4467876.4 | R20: {='Projected Rate of Motorization '!C18} -> 161.10185
A21: Eritrea | B21: =IF(countif('EV National Targets'!A:A,A21)>0, "1", "0") -> 0 | C21: =IF(countif('EV Incentives'!A:A,A21)>0, "1", "0") -> 0 | D21: {='Additional Generation For 30% E'!C19+1} -> 1.2142775 | E21: {='Grid Reliability'!F19} -> 16.8 | F21: {='Current Rate of Motorization'!B19} -> 21.515253 | G21: {='EV Charging Infrastructure'!B19} -> 2 | H21: {='Electricity Regulatory Index'!C19} -> Not Found | I21: {=' Utility Cost Recovery'!B19} -> Not Found | J21: {='Relative Affordability'!F19} -> 0.30951784 | K21: {='Access to Finance'!C19} -> Not Found | L21: {='Electricity Generated from Clea'!F19} -> 0.037538075 | M21: {='CO2 from Transportation'!E19} -> 0.36377321 | N21: {='Urban Air Quality'!I19} -> 154.57531 | O21: {='Fossil Fuel Import Dependence'!G19} -> 0.16666667 | P21: {='Fossil Fuel Subsidy Burden'!E19} -> Not Found | Q21: {='Utility Revenue Potential'!J19} -> 23289564 | R21: {='Projected Rate of Motorization '!C19} -> Not Found
A22: Eswatini | B22: =IF(countif('EV National Targets'!A:A,A22)>0, "1", "0") -> 0 | C22: =IF(countif('EV Incentives'!A:A,A22)>0, "1", "0") -> 0 | D22: {='Additional Generation For 30% E'!C20+1} -> 1.3148713 | E22: {='Grid Reliability'!K20} -> 164.28 | F22: {='Current Rate of Motorization'!B20} -> 87.37672 | G22: {='EV Charging Infrastructure'!B20} -> Not Found | H22: {='Electricity Regulatory Index'!C20} -> 0.621 | I22: {=' Utility Cost Recovery'!B20} -> 1.1157487 | J22: {='Relative Affordability'!F20} -> 0.1424021 | K22: {='Access to Finance'!C20} -> 0.33 | L22: {='Electricity Generated from Clea'!F20} -> 0.5930843 | M22: {='CO2 from Transportation'!E20} -> 0.61854143 | N22: {='Urban Air Quality'!I20} -> 220.02144 | O22: {='Fossil Fuel Import Dependence'!G20} -> 0.91954023 | P22: {='Fossil Fuel Subsidy Burden'!E20} -> Not Found | Q22: {='Utility Revenue Potential'!J20} -> 14539804 | R22: {='Projected Rate of Motorization '!C20} -> 180.1834
A23: Ethiopia | B23: =IF(countif('EV National Targets'!A:A,A23)>0, "1", "0") -> 1 | C23: =IF(countif('EV Incentives'!A:A,A23)>0, "1", "0") -> 1 | D23: {='Additional Generation For 30% E'!C21+1} -> 1.1463412 | E23: {='Grid Reliability'!F21} -> 570.72 | F23: {='Current Rate of Motorization'!B21} -> 6.7280939 | G23: {='EV Charging Infrastructure'!B21} -> 10 | H23: {='Electricity Regulatory Index'!C21} -> 0.561 | I23: {=' Utility Cost Recovery'!B21} -> 1.0270192 | J23: {='Relative Affordability'!F21} -> 0.047120138 | K23: {='Access to Finance'!C21} -> 0.05 | L23: {='Electricity Generated from Clea'!F21} -> 0.99965588 | M23: {='CO2 from Transportation'!E21} -> 0.51590766 | N23: {='Urban Air Quality'!I21} -> 143.28886 | O23: {='Fossil Fuel Import Dependence'!G21} -> 0.67662566 | P23: {='Fossil Fuel Subsidy Burden'!E21} -> 0.020507405 | Q23: {='Utility Revenue Potential'!J21} -> 49404403 | R23: {='Projected Rate of Motorization '!C21} -> 123.99302
A24: Gabon | B24: =IF(countif('EV National Targets'!A:A,A24)>0, "1", "0") -> 0 | C24: =IF(countif('EV Incentives'!A:A,A24)>0, "1", "0") -> 0 | D24: {='Additional Generation For 30% E'!C22+1} -> 1.1472259 | E24: {='Grid Reliability'!K22} -> 47.5 | F24: {='Current Rate of Motorization'!B22} -> 27.13059 | G24: {='EV Charging Infrastructure'!B22} -> Not Found | H24: {='Electricity Regulatory Index'!C22} -> 0.168 | I24: {=' Utility Cost Recovery'!B22} -> 0.90680841 | J24: {='Relative Affordability'!F22} -> 0.49154455 | K24: {='Access to Finance'!C22} -> 0.12 | L24: {='Electricity Generated from Clea'!F22} -> 0.44326082 | M24: {='CO2 from Transportation'!E22} -> 0.075063412 | N24: {='Urban Air Quality'!I22} -> 354.71596 | O24: {='Fossil Fuel Import Dependence'!G22} -> 0.28078818 | P24: {='Fossil Fuel Subsidy Burden'!E22} -> 0 | Q24: {='Utility Revenue Potential'!J22} -> 63955326 | R24: {='Projected Rate of Motorization '!C22} -> 271.31349
A25: Gambia | B25: =IF(countif('EV National Targets'!A:A,A25)>0, "1", "0") -> 1 | C25: =IF(countif('EV Incentives'!A:A,A25)>0, "1", "0") -> 0 | D25: {='Additional Generation For 30% E'!C23+1} -> 1.2199459 | E25: {='Grid Reliability'!F23} -> 191.52 | F25: {='Current Rate of Motorization'!B23} -> 36.66614 | G25: {='EV Charging Infrastructure'!B23} -> Not Found | H25: {='Electricity Regulatory Index'!C23} -> 0.298 | I25: {=' Utility Cost Recovery'!B23} -> 0.66677307 | J25: {='Relative Affordability'!F23} -> 0.4371721 | K25: {='Access to Finance'!C23} -> 0.06 | L25: {='Electricity Generated from Clea'!F23} -> 0.010067491 | M25: {='CO2 from Transportation'!E23} -> 0.1329735 | N25: {='Urban Air Quality'!I23} -> 205.18757 | O25: {='Fossil Fuel Import Dependence'!G23} -> 0.61206897 | P25: {='Fossil Fuel Subsidy Burden'!E23} -> 0 | Q25: {='Utility Revenue Potential'!J23} -> 13545146 | R25: {='Projected Rate of Motorization '!C23} -> 67.692365
A26: Ghana | B26: =IF(countif('EV National Targets'!A:A,A26)>0, "1", "0") -> 1 | C26: =IF(countif('EV Incentives'!A:A,A26)>0, "1", "0") -> 1 | D26: {='Additional Generation For 30% E'!C24+1} -> 1.122764 | E26: {='Grid Reliability'!F24} -> 107.88 | F26: {='Current Rate of Motorization'!B24} -> 69.417844 | G26: {='EV Charging Infrastructure'!B24} -> 3 | H26: {='Electricity Regulatory Index'!C24} -> 0.709 | I26: {=' Utility Cost Recovery'!B24} -> 1.0328751 | J26: {='Relative Affordability'!F24} -> 0.19721569 | K26: {='Access to Finance'!C24} -> 0.17 | L26: {='Electricity Generated from Clea'!F24} -> 0.34829234 | M26: {='CO2 from Transportation'!E24} -> 0.48124547 | N26: {='Urban Air Quality'!I24} -> 284.85389 | O26: {='Fossil Fuel Import Dependence'!G24} -> 0.94673395 | P26: {='Fossil Fuel Subsidy Burden'!E24} -> 0 | Q26: {='Utility Revenue Potential'!J24} -> 2.2868856e+08 | R26: {='Projected Rate of Motorization '!C24} -> 170.54704
A27: Guinea | B27: =IF(countif('EV National Targets'!A:A,A27)>0, "1", "0") -> 0 | C27: =IF(countif('EV Incentives'!A:A,A27)>0, "1", "0") -> 0 | D27: {='Additional Generation For 30% E'!C25+1} -> 1.1658849 | E27: {='Grid Reliability'!F25} -> 172.8 | F27: {='Current Rate of Motorization'!B25} -> 26.758394 | G27: {='EV Charging Infrastructure'!B25} -> Not Found | H27: {='Electricity Regulatory Index'!C25} -> 0.306 | I27: {=' Utility Cost Recovery'!B25} -> 0.65530793 | J27: {='Relative Affordability'!F25} -> 0.4222773 | K27: {='Access to Finance'!C25} -> 0.08 | L27: {='Electricity Generated from Clea'!F25} -> 0.72732588 | M27: {='CO2 from Transportation'!E25} -> 0.45490205 | N27: {='Urban Air Quality'!I25} -> 296.69464 | O27: {='Fossil Fuel Import Dependence'!G25} -> 0.80291971 | P27: {='Fossil Fuel Subsidy Burden'!E25} -> 0 | Q27: {='Utility Revenue Potential'!J25} -> 85273769 | R27: {='Projected Rate of Motorization '!C25} -> 105.88811
A28: Guinea-Bissau | B28: =IF(countif('EV National Targets'!A:A,A28)>0, "1", "0") -> 0 | C28: =IF(countif('EV Incentives'!A:A,A28)>0, "1", "0") -> 0 | D28: {='Additional Generation For 30% E'!C26+1} -> 1.4901597 | E28: {='Grid Reliability'!F26} -> 1116.96 | F28: {='Current Rate of Motorization'!B26} -> 33.925994 | G28: {='EV Charging Infrastructure'!B26} -> Not Found | H28: {='Electricity Regulatory Index'!C26} -> Not Found | I28: {=' Utility Cost Recovery'!B26} -> 0.81999098 | J28: {='Relative Affordability'!F26} -> 0.88300887 | K28: {='Access to Finance'!C26} -> Not Found | L28: {='Electricity Generated from Clea'!F26} -> 0.024254772 | M28: {='CO2 from Transportation'!E26} -> 0.36109422 | N28: {='Urban Air Quality'!I26} -> 241.04054 | O28: {='Fossil Fuel Import Dependence'!G26} -> 0.57746479 | P28: {='Fossil Fuel Subsidy Burden'!E26} -> 0 | Q28: {='Utility Revenue Potential'!J26} -> 15364643 | R28: {='Projected Rate of Motorization '!C26} -> 63.827001
A29: Kenya | B29: =IF(countif('EV National Targets'!A:A,A29)>0, "1", "0") -> 1 | C29: =IF(countif('EV Incentives'!A:A,A29)>0, "1", "0") -> 1 | D29: {='Additional Generation For 30% E'!C27+1} -> 1.2520136 | E29: {='Grid Reliability'!F27} -> 264.48 | F29: {='Current Rate of Motorization'!B27} -> 53.906771 | G29: {='EV Charging Infrastructure'!B27} -> 18 | H29: {='Electricity Regulatory Index'!C27} -> 0.695 | I29: {=' Utility Cost Recovery'!B27} -> 0.89335742 | J29: {='Relative Affordability'!F27} -> 0.2728122 | K29: {='Access to Finance'!C27} -> 0.4 | L29: {='Electricity Generated from Clea'!F27} -> 0.91985277 | M29: {='CO2 from Transportation'!E27} -> 0.66008455 | N29: {='Urban Air Quality'!I27} -> 150.175 | O29: {='Fossil Fuel Import Dependence'!G27} -> 0.85497889 | P29: {='Fossil Fuel Subsidy Burden'!E27} -> 0 | Q29: {='Utility Revenue Potential'!J27} -> 4.2641938e+08 | R29: {='Projected Rate of Motorization '!C27} -> 173.87863
A30: Lesotho | B30: =IF(countif('EV National Targets'!A:A,A30)>0, "1", "0") -> 0 | C30: =IF(countif('EV Incentives'!A:A,A30)>0, "1", "0") -> 0 | D30: {='Additional Generation For 30% E'!C28+1} -> 1.3166286 | E30: {='Grid Reliability'!F28} -> 98.04 | F30: {='Current Rate of Motorization'!B28} -> 390.28683 | G30: {='EV Charging Infrastructure'!B28} -> Not Found | H30: {='Electricity Regulatory Index'!C28} -> 0.49 | I30: {=' Utility Cost Recovery'!B28} -> 0.9839143 | J30: {='Relative Affordability'!F28} -> 0.043254185 | K30: {='Access to Finance'!C28} -> 0.19 | L30: {='Electricity Generated from Clea'!F28} -> 1 | M30: {='CO2 from Transportation'!E28} -> 0.23275228 | N30: {='Urban Air Quality'!I28} -> 177.97847 | O30: {='Fossil Fuel Import Dependence'!G28} -> 0.77729258 | P30: {='Fossil Fuel Subsidy Burden'!E28} -> 0 | Q30: {='Utility Revenue Potential'!J28} -> 3015311.2 | R30: {='Projected Rate of Motorization '!C28} -> 64.130654
A31: Liberia | B31: =IF(countif('EV National Targets'!A:A,A31)>0, "1", "0") -> 0 | C31: =IF(countif('EV Incentives'!A:A,A31)>0, "1", "0") -> 0 | D31: {='Additional Generation For 30% E'!C29+1} -> 1.0977625 | E31: {='Grid Reliability'!F29} -> 448.2 | F31: {='Current Rate of Motorization'!B29} -> 13.386889 | G31: {='EV Charging Infrastructure'!B29} -> Not Found | H31: {='Electricity Regulatory Index'!C29} -> 0.628 | I31: {=' Utility Cost Recovery'!B29} -> 0.96066649 | J31: {='Relative Affordability'!F29} -> 0.66403651 | K31: {='Access to Finance'!C29} -> 0.17 | L31: {='Electricity Generated from Clea'!F29} -> 0.58028845 | M31: {='CO2 from Transportation'!E29} -> 0.61121477 | N31: {='Urban Air Quality'!I29} -> 278.72428 | O31: {='Fossil Fuel Import Dependence'!G29} -> 0.47058824 | P31: {='Fossil Fuel Subsidy Burden'!E29} -> 0 | Q31: {='Utility Revenue Potential'!J29} -> 21771295 | R31: {='Projected Rate of Motorization '!C29} -> 75.529086
A32: Libya | B32: =IF(countif('EV National Targets'!A:A,A32)>0, "1", "0") -> 0 | C32: =IF(countif('EV Incentives'!A:A,A32)>0, "1", "0") -> 0 | D32: {='Additional Generation For 30% E'!C30+1} -> 1.4325801 | E32: {='Grid Reliability'!K30} -> 1883.4 | F32: {='Current Rate of Motorization'!B30} -> 436.15322 | G32: {='EV Charging Infrastructure'!B30} -> 10 | H32: {='Electricity Regulatory Index'!C30} -> Not Found | I32: {=' Utility Cost Recovery'!B30} -> Not Found | J32: {='Relative Affordability'!F30} -> 3.4113526 | K32: {='Access to Finance'!C30} -> Not Found | L32: {='Electricity Generated from Clea'!F30} -> 0.00024984004 | M32: {='CO2 from Transportation'!E30} -> 0.42673024 | N32: {='Urban Air Quality'!I30} -> 194.2928 | O32: {='Fossil Fuel Import Dependence'!G30} -> 1.0972273 | P32: {='Fossil Fuel Subsidy Burden'!E30} -> 0.037156573 | Q32: {='Utility Revenue Potential'!J30} -> 5.6790854e+08 | R32: {='Projected Rate of Motorization '!C30} -> 342.88149
A33: Madagascar | B33: =IF(countif('EV National Targets'!A:A,A33)>0, "1", "0") -> 0 | C33: =IF(countif('EV Incentives'!A:A,A33)>0, "1", "0") -> 1 | D33: {='Additional Generation For 30% E'!C31+1} -> 1.3351523 | E33: {='Grid Reliability'!F31} -> 294.84 | F33: {='Current Rate of Motorization'!B31} -> 9.2925868 | G33: {='EV Charging Infrastructure'!B31} -> 2 | H33: {='Electricity Regulatory Index'!C31} -> 0.329 | I33: {=' Utility Cost Recovery'!B31} -> 0.66304927 | J33: {='Relative Affordability'!F31} -> 0.1935474 | K33: {='Access to Finance'!C31} -> 0.09 | L33: {='Electricity Generated from Clea'!F31} -> 0.35519559 | M33: {='CO2 from Transportation'!E31} -> 0.44038867 | N33: {='Urban Air Quality'!I31} -> 187.95872 | O33: {='Fossil Fuel Import Dependence'!G31} -> 0.75560081 | P33: {='Fossil Fuel Subsidy Burden'!E31} -> 0.0065371471 | Q33: {='Utility Revenue Potential'!J31} -> 68748691 | R33: {='Projected Rate of Motorization '!C31} -> 40.539373
A34: Malawi | B34: =IF(countif('EV National Targets'!A:A,A34)>0, "1", "0") -> 0 | C34: =IF(countif('EV Incentives'!A:A,A34)>0, "1", "0") -> 1 | D34: {='Additional Generation For 30% E'!C32+1} -> 1.156827 | E34: {='Grid Reliability'!F32} -> 345.72 | F34: {='Current Rate of Motorization'!B32} -> 16.715 | G34: {='EV Charging Infrastructure'!B32} -> Not Found | H34: {='Electricity Regulatory Index'!C32} -> 0.479 | I34: {=' Utility Cost Recovery'!B32} -> 0.9244442 | J34: {='Relative Affordability'!F32} -> 0.23069653 | K34: {='Access to Finance'!C32} -> 0.1 | L34: {='Electricity Generated from Clea'!F32} -> 0.85957368 | M34: {='CO2 from Transportation'!E32} -> 0.75303907 | N34: {='Urban Air Quality'!I32} -> 229.79604 | O34: {='Fossil Fuel Import Dependence'!G32} -> 0.74233129 | P34: {='Fossil Fuel Subsidy Burden'!E32} -> 0 | Q34: {='Utility Revenue Potential'!J32} -> 32168710 | R34: {='Projected Rate of Motorization '!C32} -> 46.351633
A35: Mali | B35: =IF(countif('EV National Targets'!A:A,A35)>0, "1", "0") -> 0 | C35: =IF(countif('EV Incentives'!A:A,A35)>0, "1", "0") -> 0 | D35: {='Additional Generation For 30% E'!C33+1} -> 1.2231562 | E35: {='Grid Reliability'!F33} -> 257.04 | F35: {='Current Rate of Motorization'!B33} -> 18.414067 | G35: {='EV Charging Infrastructure'!B33} -> 2 | H35: {='Electricity Regulatory Index'!C33} -> 0.45 | I35: {=' Utility Cost Recovery'!B33} -> 0.83303821 | J35: {='Relative Affordability'!F33} -> 0.28197141 | K35: {='Access to Finance'!C33} -> 0.13 | L35: {='Electricity Generated from Clea'!F33} -> 0.3225882 | M35: {='CO2 from Transportation'!E33} -> 0.4200028 | N35: {='Urban Air Quality'!I33} -> 251.7394 | O35: {='Fossil Fuel Import Dependence'!G33} -> 0.77553311 | P35: {='Fossil Fuel Subsidy Burden'!E33} -> 0 | Q35: {='Utility Revenue Potential'!J33} -> 1.1795194e+08 | R35: {='Projected Rate of Motorization '!C33} -> 57.348575
A36: Mauritania | B36: =IF(countif('EV National Targets'!A:A,A36)>0, "1", "0") -> 0 | C36: =IF(countif('EV Incentives'!A:A,A36)>0, "1", "0") -> 0 | D36: {='Additional Generation For 30% E'!C34+1} -> 1.1724362 | E36: {='Grid Reliability'!F34} -> 165.36 | F36: {='Current Rate of Motorization'!B34} -> 10.118735 | G36: {='EV Charging Infrastructure'!B34} -> 5 | H36: {='Electricity Regulatory Index'!C34} -> 0.226 | I36: {=' Utility Cost Recovery'!B34} -> 0.46432605 | J36: {='Relative Affordability'!F34} -> 0.36977796 | K36: {='Access to Finance'!C34} -> 0.12 | L36: {='Electricity Generated from Clea'!F34} -> 0.2659655 | M36: {='CO2 from Transportation'!E34} -> 0.44233319 | N36: {='Urban Air Quality'!I34} -> 188.39258 | O36: {='Fossil Fuel Import Dependence'!G34} -> 0.60697306 | P36: {='Fossil Fuel Subsidy Burden'!E34} -> 0 | Q36: {='Utility Revenue Potential'!J34} -> 52401519 | R36: {='Projected Rate of Motorization '!C34} -> 82.68596
A37: Mauritius | B37: =IF(countif('EV National Targets'!A:A,A37)>0, "1", "0") -> 0 | C37: =IF(countif('EV Incentives'!A:A,A37)>0, "1", "0") -> 1 | D37: {='Additional Generation For 30% E'!C35+1} -> 1.1247071 | E37: {='Grid Reliability'!F35} -> 48 | F37: {='Current Rate of Motorization'!B35} -> 401.72281 | G37: {='EV Charging Infrastructure'!B35} -> 31 | H37: {='Electricity Regulatory Index'!C35} -> 0.32 | I37: {=' Utility Cost Recovery'!B35} -> 1.0551605 | J37: {='Relative Affordability'!F35} -> 0.20246605 | K37: {='Access to Finance'!C35} -> 0.2 | L37: {='Electricity Generated from Clea'!F35} -> 0.23920742 | M37: {='CO2 from Transportation'!E35} -> 0.27210903 | N37: {='Urban Air Quality'!I35} -> 192.98179 | O37: {='Fossil Fuel Import Dependence'!G35} -> 0.79318735 | P37: {='Fossil Fuel Subsidy Burden'!E35} -> 0 | Q37: {='Utility Revenue Potential'!J35} -> 42822877 | R37: {='Projected Rate of Motorization '!C35} -> 642.65853
A38: Morocco | B38: =IF(countif('EV National Targets'!A:A,A38)>0, "1", "0") -> 1 | C38: =IF(countif('EV Incentives'!A:A,A38)>0, "1", "0") -> 1 | D38: {='Additional Generation For 30% E'!C36+1} -> 1.1397201 | E38: {='Grid Reliability'!F36} -> 0.72 | F38: {='Current Rate of Motorization'!B36} -> 104.79005 | G38: T | H38: {='Electricity Regulatory Index'!C36} -> Not Found | I38: {=' Utility Cost Recovery'!B36} -> 1.1086 | J38: {='Relative Affordability'!F36} -> 0.18461001 | K38: {='Access to Finance'!C36} -> 0.05 | L38: {='Electricity Generated from Clea'!F36} -> 0.19879636 | M38: {='CO2 from Transportation'!E36} -> 0.26739569 | N38: {='Urban Air Quality'!I36} -> 171.0313 | O38: {='Fossil Fuel Import Dependence'!G36} -> 0.84156408 | P38: {='Fossil Fuel Subsidy Burden'!E36} -> 0 | Q38: {='Utility Revenue Potential'!J36} -> 6.0945878e+08 | R38: {='Projected Rate of Motorization '!C36} -> 223.2537
A39: Mozambique | B39: =IF(countif('EV National Targets'!A:A,A39)>0, "1", "0") -> 1 | C39: =IF(countif('EV Incentives'!A:A,A39)>0, "1", "0") -> 0 | D39: {='Additional Generation For 30% E'!C37+1} -> 1.0680904 | E39: {='Grid Reliability'!F37} -> 103.68 | F39: {='Current Rate of Motorization'!B37} -> 25.232942 | G39: {='EV Charging Infrastructure'!B37} -> Not Found | H39: {='Electricity Regulatory Index'!C37} -> 0.372 | I39: {=' Utility Cost Recovery'!B37} -> 1.0694158 | J39: {='Relative Affordability'!F37} -> 0.15284832 | K39: {='Access to Finance'!C37} -> 0.15 | L39: {='Electricity Generated from Clea'!F37} -> 0.81325134 | M39: {='CO2 from Transportation'!E37} -> 0.56015526 | N39: {='Urban Air Quality'!I37} -> 235.89201 | O39: {='Fossil Fuel Import Dependence'!G37} -> 0.93195021 | P39: {='Fossil Fuel Subsidy Burden'!E37} -> 0 | Q39: {='Utility Revenue Potential'!J37} -> 1.0844203e+08 | R39: {='Projected Rate of Motorization '!C37} -> 74.91192
A40: Namibia | B40: =IF(countif('EV National Targets'!A:A,A40)>0, "1", "0") -> 1 | C40: =IF(countif('EV Incentives'!A:A,A40)>0, "1", "0") -> 0 | D40: {='Additional Generation For 30% E'!C38+1} -> 1.4798864 | E40: {='Grid Reliability'!F38} -> 41.76 | F40: {='Current Rate of Motorization'!B38} -> 152.94023 | G40: {='EV Charging Infrastructure'!B38} -> 6 | H40: {='Electricity Regulatory Index'!C38} -> 0.618 | I40: {=' Utility Cost Recovery'!B38} -> 1.0610175 | J40: {='Relative Affordability'!F38} -> 0.28745382 | K40: {='Access to Finance'!C38} -> 0.23 | L40: {='Electricity Generated from Clea'!F38} -> 0.95586922 | M40: {='CO2 from Transportation'!E38} -> 0.53451195 | N40: {='Urban Air Quality'!I38} -> 173.39559 | O40: {='Fossil Fuel Import Dependence'!G38} -> 0.56798457 | P40: {='Fossil Fuel Subsidy Burden'!E38} -> 0 | Q40: {='Utility Revenue Potential'!J38} -> 1.1130471e+08 | R40: {='Projected Rate of Motorization '!C38} -> 205.31589
...

Sheet EV National Targets
A1: Country | B1: Level | C1: Policy type | D1: Key policy measures and targets | E1: Year announced | F1: Category | G1: Source | H1: Source 2
A2: Algeria | B2: National | C2: Target | D2: 1,000 charging stations by 2024 | E2: 2023 | G2: Source | H2: Climatescope
A3: Cabo Verde | B3: Multi-national | C3: Ambition | D3: COP26 Declaration: Work towards all sales of new cars and vans being zero emission globally by 2040, or by no later than 2035 in leading markets. | E3: 2022 | F3: LDV | G3: Accelerating to Zero Coalition | H3: IEA
A4: Cabo Verde | B4: National | C4: Target | D4: 50% share of EVs in urban bus sales by 2025, 75% by 2030 and 100% by 2040. | E4: 2019 | F4: Bus | G4: Government of Cabo Verde | H4: IEA
A5: Cabo Verde | B5: National | C5: Target | D5: 35% share of passenger LDV sales to be EVs by 2025, 70% by 2030 and 100% by 2035. | E5: 2019 | F5: LDV | G5: Government of Cabo Verde | H5: IEA
A6: Cabo Verde | B6: National | C6: Target | D6: 25% share of EVs in heavy truck sales by 2030 and 100% by 2035. | E6: 2019 | F6: M/HDV | G6: Government of Cabo Verde | H6: IEA
A7: Cabo Verde | B7: National | C7: Target | D7: 15% share of EVs in medium truck sales by 2025, 35% by 2030 and 100% by 2035. | E7: 2019 | F7: M/HDV | G7: Government of Cabo Verde | H7: IEA
A8: Cabo Verde | B8: National | C8: Target | D8: 100% EVs in government LDV stock by 2035. | E8: 2019 | F8: LDV | G8: Government of Cabo Verde, source | H8: IEA
A9: Ethiopia | B9: National | C9: Target | D9: Introduce 500,000 EVs in the Ethiopian market by 2030 | E9: 2024 | G9: Source, Source
A10: Gambia | B10: National | C10: Target | D10: Promote low emission fuel and HEVs, introduce an age limit of a maximum of 3 years for imported vehicles. | E10: 2022 | F10: LDV | G10: Government of Gambia | H10: IEA
A11: Ghana | B11: National | C11: Target | D11: Build 1,000 electric vehicle charging stations across the country within five years | E11: 2023 | G11: Source | H11: Climatescope
A12: Ghana | B12: National | C12: Ambition | D12: 4%, 16%, and 32% of cars sold to be EVs in 2025, 2030, and 2050 respectively. | E12: 2022 | F12: LDV | G12: Government of Ghana | H12: IEA
A13: Ghana | B13: National | C13: Ambition | D13: 4%, 16%, and 32% of buses sold to be EVs in 2025, 2030, and 2050 respectively. | E13: 2022 | F13: Bus | G13: Government of Ghana | H13: IEA
A14: Ghana | B14: Multi-national | C14: Ambition | D14: COP26 Declaration: Work intensely towards accelerated proliferation and adoption of zero-emission vehicles. | E14: 2022 | F14: LDV | G14: Accelerating to Zero Coalition | H14: IEA
A15: Kenya | B15: Multi-national | C15: Ambition | D15: COP26 Declaration: Work intensely towards accelerated proliferation and adoption of zero-emission vehicles. | E15: 2022 | F15: LDV | G15: Accelerating to Zero Coalition | H15: IEA
A16: Kenya | B16: Natiional | C16: Target | D16: 200,000 electric motorcycles on its roads by end of 2024 | E16: 2023 | G16: Source, Source | H16: Non-IEA
A17: Kenya | B17: National | C17: Ambition | D17: 5% share of electric/hybrid vehicles in total vehicles imported by 2025. | E17: 2020 | F17: Multiple | G17: Government of Kenya | H17: IEA
A18: Morocco | B18: Multi-national | C18: Ambition | D18: COP26 Declaration: Work intensely towards accelerated proliferation and adoption of zero-emission vehicles. | E18: 2022 | F18: LDV | G18: Accelerating to Zero Coalition | H18: IEA
A19: Mozambique | B19: National | C19: Ambition | D19: Set up an electric bus assembly plant in the country to assemble around 1,000 buses in first phase | E19: 2023 | G19: Source | H19: Climatescope
A20: Namibia | B20: National | C20: Target | D20: Aims to have 96,500 light vehicles converted to BEVs by 2025 | E20: 2024 | G20: Source
A21: Nigeria | B21: National | C21: Ambition | D21: 100% transition to EV by 2060 with interim targets of 1% EV and 2% HEV by 2030, and 60% EV and 20% HEV by 2050. | E21: 2020 | F21: LDV | G21: Government of Nigeria | H21: IEA
A22: Rwanda | B22: Multi-national | C22: Ambition | D22: COP26 Declaration: Work intensely towards accelerated proliferation and adoption of zero-emission vehicles. | E22: 2022 | F22: LDV | G22: Accelerating to Zero Coalition | H22: IEA
A23: Seychelles | B23: National | C23: Target | D23: 30% of new private vehicle sales to be electric by 2030 | E23: 2022 | F23: LDV | G23: Government of Seychelles | H23: IEA
A24: Seychelles | B24: National | C24: Target | D24: 100% of public bus stock to be electric by 2050. | E24: 2022 | F24: Bus | G24: Government of Seychelles | H24: IEA
A25: South Africa | B25: National | C25: Target | D25: Convert 5% of the public and national fleet to cleaner alternative fuel and efficient technology vehicles by 2025, with annual increase of 2% thereafter. | E25: 2018 | F25: Multiple | G25: Government of South Africa | H25: IEA
A26: South Africa | B26: National | C26: Target | D26: Add 40 solar powered public EV charging stations per annum. | E26: 2018 | F26: EVSE | G26: Government of South Africa
A27: Tunisia | B27: National | C27: Target | D27: 130,000 EVs by 2030 | E27: 2023 | G27: Source
A28: Zimbabwe | B28: National | C28: Target (draft) | D28: 33% market penetration of e-vehicles by 2030 | E28: 2022 | G28: Source
C30: Link to methodology
C31: {={"INDICATOR INFORMATION"; "Index Category: "&CHAR(10)& "EV Readiness Index - Measures country preparedness to adopt EVs at large scale"; ""; "Sub-Category: "&CHAR(10)& "Enabling Policies"; ""; "Indicator Name: "&CHAR(10)& "EV National Targets"; ""; "Description: "&CHAR(10)& "Records key ambitions and targets that support the deployment of electric vehicles (EVs) in Africa."; ""; "Scoring Categories: "&CHAR(10)& "• No EV-specific targets = Low Readiness (1/3)"&CHAR(10)& "• Has EV-specific targets = High Readiness (3/3)"; ""; "Focus: "&CHAR(10)& "• EV-specific ambitions and penetration targets"; ""; "Data Categories: "&CHAR(10)& "• National Targets"&CHAR(10)& "• National Ambitions"&CHAR(10)& "• Multi-national Commitments"; ""; "Last Updated: 2022"; ""; "Primary Sources: "&CHAR(10)& "• IEA"&CHAR(10)& "• Government Documents"&CHAR(10)& "• Climatescope"}} -> INDICATOR INFORMATION
C32: Index Category: EV Readiness Index - Measures country preparedness to adopt EVs at large scale
C34: Sub-Category: Enabling Policies
C36: Indicator Name: EV National Targets
C38: Description: Records key ambitions and targets that support the deployment of electric vehicles (EVs) in Africa.
C40: Scoring Categories: • No EV-specific targets = Low Readiness (1/3) • Has EV-specific targets = High Readiness (3/3)
C42: Focus: • EV-specific ambitions and penetration targets
C44: Data Categories: • National Targets • National Ambitions • Multi-national Commitments
C46: Last Updated: 2022
C48: Primary Sources: • IEA • Government Documents • Climatescope

Sheet EV Incentives
A1: Country | B1: Level | C1: Policy type | D1: Key policy measures and targets | E1: Year announced | F1: Category | G1: Source | H1: Source
A2: Angola | B2: National | C2: Legislation | D2: 50% reduction of both import duty and vehicle tax for EVs. | E2: 2022 | F2: Multiple | G2: Government of Angola | H2: IEA
A3: Angola | B3: National | C3: Legislation | D3: 50% reduction in import customs duty and motor vehicle tax for EVs until 2032 | E3: 2022 | G3: Source | H3: Climatescope
A4: Benin | B4: National | C4: Legislation | D4: Exempt 100% EVs from VAT and custom duties | E4: 2023 | G4: Source
A5: Cabo Verde | B5: National | C5: Legislation | D5: Exemption from VAT and excise duties on the import of EVs, including two-wheeler vehicles | E5: 2022 | F5: EVSE | G5: ICCT
A6: DR Congo | B6: Multi-national | C6: Legislation (agreement) | D6: Afreximbank and ECA sign Framework Agreement towards establishing Special Economic Zones for the production of Battery Electric Vehicles in DRC and Zambia | E6: 2023 | G6: Source
A7: Egypt | B7: National | C7: Legislation | D7: Ministerial Resolution 255/2018 exempts EVs from customs duties and allowed the import of EVs that are no older than three years | E7: 2018 | G7: Source | H7: Climatescope
A8: Egypt | B8: National | C8: Legislation (announced) | D8: Financial support up to EGP 50,000 for buyers of locally-manufactured electric cars | E8: 2021 | G8: Source | H8: Climatescope
A9: Ethiopia | B9: National | C9: Legislation | D9: EVs are not subject to import duties if locally assembled, reduced rates apply for partially and fully assembled imports, also exempt from VAT, surtax, and excise tax. | E9: 2022 | F9: Multiple | G9: Government of Ethiopia | H9: IEA
A10: Ethiopia | B10: National | C10: Legislation | D10: Exempts EVs from VAT, excise tax, and surtaxes, reduces import tax | E10: 2022 | G10: Source | H10: Climatescope
A11: Ethiopia | B11: National | C11: Legislation (announced) | D11: An immediate ban on all ICE vehicle imports | E11: 2024 | G11: Source
A12: Ethiopia | B12: National | C12: Legislation | D12: National 10-year strategic plan: Importing 439,000 EVs by 2030 | E12: 2020 | G12: Source
A13: Ghana | B13: National | C13: Legislation | D13: Waive import duties on import of EVs for public transportation for 8 years | E13: 2023 | F13: EVSE | G13: Clean Technica | H13: ITA
A14: Kenya | B14: National | C14: Legislation | D14: Finance Bill of 2019 proposed reduction on the excise duty for all vehicles with only electric motor for propulsion (BEVs) from 20% to 10%. | E14: 2019 | G14: Source
A15: Kenya | B15: National | C15: Legislation | D15: Kenya released draft of National E-mobility policy that will institure ZEVs sales targets and investment criteria for domestic manafacturers and assemblers to be eligible for gov incentives | E15: 2024 | G15: Source | H15: Policy
A16: Madagascar | B16: National | C16: Legislation | D16: Exempts electric and hybrid vehicles from VAT | E16: 2024 | G16: Source
